<?xml version="1.0"?>
<robot  name="planar_3link" xmlns:xacro="http://ros.org/wiki/xacro">

  <material name="blue">
    <color rgba="0.0 0.0 0.8 0.5"/>
  </material>
  <material name="red">
    <color rgba="0.8 0.0 0.0 0.5"/>
  </material>
  <material name="grey">
    <color rgba="0.4 0.4 0.4 0.5" />
  </material>
  <material name="green">
    <color rgba="0.0 0.8 0.0 0.5" />
  </material>
  <material name="Cyan">
    <color rgba="0 1.0 1.0 0.5"/>
  </material>

  <link name="world" />

  <!-- Link 1 -->
  <link name="base_link">
    <visual>
      <geometry>
        <cylinder length="0.05" radius="0.1" />
      </geometry>
      <origin rpy="0 1.57075 0" xyz="-0.025 0 0"/>
      <material name="Cyan">
      </material>    </visual>
    <collision>
      <geometry>
        <cylinder length="0.05" radius="0.1" />
      </geometry>
      <origin rpy="0 1.57075 0" xyz="-0.025 0 0"/>
      <material name="grey"/>
    </collision>
  </link>
  <!-- base Joint (fixed) -->
  <joint name="fixed_joint" type="fixed">
    <parent link="world" />
    <child link="base_link" />
    <origin xyz="0 0 0" rpy="0 0 0" />
  </joint>

  <!-- First link segment with link length a1 -->
  <link name="link_1">
    <visual>
      <origin rpy="0 1.57075 0" xyz="0.5 0 0"/>
      <geometry>
        <cylinder length="1.0" radius="0.02" />
      </geometry>
      <material name="red"/>
    </visual>
    <collision>
      <origin rpy="0 1.57075 0" xyz="0.5 0 0"/>
      <geometry>
        <cylinder length="1.0" radius="0.02" />
      </geometry>
      <material name="grey"/>
    </collision>
    <inertial>
      <origin xyz="0.5 0 .01" rpy="0 0 0" />
      <mass value="1" />
      <inertia ixx="1.0" ixy="0.0" ixz="0.0" iyy="1.0" iyz="0.0" izz="1.0" />
    </inertial>
  </link>
  <!-- Joint 1 (R) -->
  <joint name="joint_1" type="revolute">
    <parent link="base_link" />
    <child link="link_1" />
    <origin xyz="0.0 0 0.0" rpy="0 0 0" />
    <axis xyz="0 0 1" />
    <limit lower="-1.57" upper="1.57" effort="0" velocity="0.5" />
  </joint>

  <!-- First link segment with link length a2 -->
  <link name="link_2">
    <visual>
      <origin rpy="0 1.57075 0" xyz="0.25 0 0"/>
      <geometry>
        <cylinder length="0.5" radius="0.02" />
      </geometry>
      <material name="green"/>
    </visual>
    <collision>
      <origin rpy="0 1.57075 0" xyz="0.25 0 0"/>
      <geometry>
        <cylinder length="0.5" radius="0.02" />
      </geometry>
      <material name="grey"/>
    </collision>
    <inertial>
      <origin xyz="0.25 0 .01" rpy="0 0 0" />
      <mass value="1" />
      <inertia ixx="0.5" ixy="0.0" ixz="0.0" iyy="0.5" iyz="0.0" izz="0.5" />
    </inertial>
  </link>
  <joint name="joint_2" type="revolute">
    <parent link="link_1" />
    <child link="link_2" />
    <origin xyz="1.0 0.0 0.0" rpy="0.0 0 0.0" />
    <axis xyz="0 0 1" />
    <limit lower="-1.57" upper="1.57" effort="0" velocity="0.5" />
  </joint>

  <link name="link_3">
    <visual>
      <origin rpy="0 1.57075 0" xyz="0.25 0 0"/>
      <geometry>
        <cylinder length="0.5" radius="0.02" />
      </geometry>
      <material name="blue"/>
    </visual>
    <collision>
      <origin rpy="0 1.57075 0" xyz="0.25 0 0"/>
      <geometry>
        <cylinder length="0.5" radius="0.02" />
      </geometry>
      <material name="grey"/>
    </collision>
    <inertial>
      <origin xyz="0.25 0 .01" rpy="0 0 0" />
      <mass value="1" />
      <inertia ixx="0.5" ixy="0.0" ixz="0.0" iyy="0.5" iyz="0.0" izz="0.5" />
    </inertial>
  </link>
  <joint name="joint_3" type="revolute">
    <parent link="link_2" />
    <child link="link_3" />
    <origin xyz="0.5 0.0 0.0" rpy="0.0 0 0.0" />
    <axis xyz="0 0 1" />
    <limit lower="-1.57" upper="1.57" effort="0" velocity="0.5" />
  </joint>

  <link name="end_effector" />

 <joint name="gripper_end" type="fixed">
    <parent link="link_3" />
    <child link="end_effector" />
    <origin xyz="0.5 0 0" rpy="0 0 0" />
  </joint>
  
</robot>
